# TclError Fix - Visual Workflow Comparison

## The Problem

### Before Fix - Application Crashes

```
User starts restore operation:
┌─────────────────────────────────────┐
│  Restoring Nextcloud...             │
│  Progress: 45%                      │
│  ████████░░░░░░░░░░░░ 45%          │
│  Status: Extracting backup files... │
└─────────────────────────────────────┘
                │
                │ User clicks "Return to Main Menu"
                │ (or closes window)
                ↓
┌─────────────────────────────────────┐
│  Main Menu                          │
│  [Start Backup]                     │
│  [Restore Backup]                   │
└─────────────────────────────────────┘
                │
                │ Background restore thread tries to update
                │ progress_bar.value = 50
                ↓
┌─────────────────────────────────────┐
│  ⚠️ APPLICATION CRASH               │
│                                     │
│  TclError: invalid command name     │
│  ".!frame.!progressbar"             │
│                                     │
│  Stack trace...                     │
└─────────────────────────────────────┘
```

**Result:** Application crashes, user loses work, bad experience

---

### After Fix - Graceful Handling

```
User starts restore operation:
┌─────────────────────────────────────┐
│  Restoring Nextcloud...             │
│  Progress: 45%                      │
│  ████████░░░░░░░░░░░░ 45%          │
│  Status: Extracting backup files... │
└─────────────────────────────────────┘
                │
                │ User clicks "Return to Main Menu"
                │ (or closes window)
                ↓
┌─────────────────────────────────────┐
│  Main Menu                          │
│  [Start Backup]                     │
│  [Restore Backup]                   │
└─────────────────────────────────────┘
                │
                │ Background thread checks widget existence
                │ safe_widget_update(progress_bar, ...)
                ↓
┌─────────────────────────────────────┐
│  📝 Debug Log:                      │
│  "Widget no longer exists"          │
│  "User navigated away"              │
│  ✓ Continue normally                │
└─────────────────────────────────────┘
                │
                ↓
        Application continues
        running normally
```

**Result:** No crash, user can continue using app, professional behavior

---

## Code Flow Comparison

### Before: Unsafe Widget Update

```python
def set_restore_progress(self, percent, msg=""):
    # Direct widget access - crashes if widget destroyed!
    self.progressbar['value'] = percent           # 💥 CRASH HERE
    self.progress_label.config(text=f"{percent}%")
    if msg:
        self.status_label.config(text=msg)
    self.update_idletasks()                       # 💥 OR HERE
```

**Problems:**
1. No check if widget exists
2. No TclError handling
3. update_idletasks() can also crash
4. Background thread doesn't know widget is gone

---

### After: Safe Widget Update

```python
def set_restore_progress(self, percent, msg=""):
    # Safe widget access - handles destruction gracefully
    if hasattr(self, "progressbar") and self.progressbar:
        safe_widget_update(                       # ✅ SAFE
            self.progressbar,
            lambda: setattr(self.progressbar, 'value', percent),
            "progress bar value update"
        )
    if hasattr(self, "progress_label") and self.progress_label:
        safe_widget_update(                       # ✅ SAFE
            self.progress_label,
            lambda: self.progress_label.config(text=f"{percent}%"),
            "progress label update"
        )
    if msg and hasattr(self, "status_label") and self.status_label:
        safe_widget_update(                       # ✅ SAFE
            self.status_label,
            lambda: self.status_label.config(text=msg),
            "status label update"
        )
    try:
        if self.winfo_exists():                   # ✅ CHECK FIRST
            self.update_idletasks()
    except tk.TclError:                           # ✅ CATCH
        logger.debug("Window closed - skipping update")
```

**Improvements:**
1. ✓ Check if attribute exists
2. ✓ Check if widget exists (winfo_exists)
3. ✓ Catch TclError specifically
4. ✓ Log as debug (not error)
5. ✓ Return gracefully without crashing

---

## Safe Widget Update Helper Function

```python
def safe_widget_update(widget, update_func, error_context="widget update"):
    """
    Safely update a widget, catching TclError if destroyed.
    
    Flow:
    1. Check widget is not None
    2. Check widget.winfo_exists()
    3. Call update_func()
    4. Catch TclError if widget destroyed between check and update
    5. Log as debug, not error (expected behavior)
    """
    
    if widget is None:                            # 1️⃣ NULL CHECK
        logger.debug(f"Skipping {error_context}: widget is None")
        return False
    
    try:
        if not widget.winfo_exists():             # 2️⃣ EXISTENCE CHECK
            logger.debug(f"Skipping {error_context}: widget gone")
            return False
        
        update_func()                             # 3️⃣ SAFE UPDATE
        return True
    except tk.TclError as e:                      # 4️⃣ CATCH TCLERROR
        logger.debug(f"TclError during {error_context}: {e}")
        return False                              # 5️⃣ GRACEFUL RETURN
    except Exception as e:
        logger.error(f"Unexpected error during {error_context}: {e}")
        return False
```

---

## Exception Handling Hierarchy

### Before: All Exceptions Treated Equally

```python
try:
    # Restore operations...
    self.process_label.config(text="Processing...")
    # ... more code ...
except Exception as e:                            # ❌ CATCHES EVERYTHING
    logger.error(f"RESTORE FAILED: {e}")          # ❌ LOGS AS ERROR
    show_error_dialog(e)                          # ❌ SHOWS TO USER
```

**Problems:**
- TclError (expected) treated same as real errors
- User sees error dialog for expected behavior
- Logs filled with false positives
- Difficult to debug actual issues

---

### After: Specific Exception Handling

```python
try:
    # Restore operations...
    safe_widget_update(
        self.process_label,
        lambda: self.process_label.config(text="Processing..."),
        "process label update"
    )
    # ... more code ...
except tk.TclError as e:                          # ✅ CATCH TCLERROR FIRST
    logger.info("Restore thread terminated")       # ✅ INFO LEVEL
    logger.debug(f"TclError: {e}")                 # ✅ DEBUG DETAILS
    # Don't show error - expected behavior        ✅ NO DIALOG
except Exception as e:                            # ✅ THEN REAL ERRORS
    logger.error(f"RESTORE FAILED: {e}")          # ✅ ERROR LEVEL
    show_error_dialog(e)                          # ✅ SHOW DIALOG
```

**Improvements:**
1. ✓ TclError caught before general Exception
2. ✓ TclError logged as info/debug, not error
3. ✓ No error dialog for TclError (expected)
4. ✓ Real errors still reported properly
5. ✓ Clear logs for debugging

---

## Real-World Scenarios

### Scenario 1: User Navigates Away During Restore

```
Timeline:
00:00 - User starts restore
00:30 - Extraction begins (background thread)
00:45 - User clicks "Return to Main Menu"
        ├─ Widgets destroyed
        └─ Background thread still running
00:46 - Thread tries: progress_bar['value'] = 60
        
Before Fix:
  💥 CRASH: TclError: invalid command name
        
After Fix:
  ✓ safe_widget_update checks widget.winfo_exists()
  ✓ Returns False, thread continues
  ✓ Logs: "Widget no longer exists (debug)"
  ✓ No crash, no error message
```

### Scenario 2: User Closes Window Mid-Operation

```
Timeline:
00:00 - User starts restore
01:00 - Database restore in progress
01:15 - User closes entire window
        └─ All widgets destroyed
01:16 - Thread tries: status_label.config(text="...")
        
Before Fix:
  💥 CRASH: TclError then application exits
        
After Fix:
  ✓ TclError caught in restore thread
  ✓ Logged: "Widget destroyed - user closed window"
  ✓ Thread terminates gracefully
  ✓ Application cleanup proceeds normally
```

### Scenario 3: Rapid Page Switching

```
Timeline:
00:00 - User on restore page
00:01 - Clicks backup
        └─ Restore widgets destroyed
00:02 - Background detection thread tries widget update
        
Before Fix:
  💥 CRASH: Widget doesn't exist
        
After Fix:
  ✓ Widget existence check fails
  ✓ Update skipped silently
  ✓ Debug log entry only
  ✓ User experience uninterrupted
```

---

## Logging Comparison

### Before Fix - Confusing Logs

```
2025-10-20 14:30:45 - ERROR - TclError: invalid command name ".!frame.!progressbar"
2025-10-20 14:30:45 - ERROR - Restore failed!
2025-10-20 14:30:45 - ERROR - Full traceback: ...
2025-10-20 14:30:50 - ERROR - TclError: invalid command name ".!frame.!label"
2025-10-20 14:31:00 - ERROR - TclError: cannot use geometry manager
```

**Problems:** 
- False positives marked as ERRORS
- Hard to find real issues
- Logs full of normal behavior

---

### After Fix - Clear Logs

```
2025-10-20 14:30:45 - DEBUG - Skipping progress bar update: widget no longer exists
2025-10-20 14:30:45 - INFO - Restore thread terminated: User navigated away
2025-10-20 14:30:45 - DEBUG - TclError during widget update (expected)
2025-10-20 14:30:50 - DEBUG - Skipping status label update: widget is None
```

**Improvements:**
- TclErrors logged as DEBUG (not ERROR)
- Clear context provided
- Easy to distinguish from real errors
- Professional logging

---

## Benefits Summary

| Aspect | Before | After |
|--------|--------|-------|
| **Stability** | ❌ Crashes | ✅ No crashes |
| **User Experience** | ❌ Data loss | ✅ Seamless |
| **Error Messages** | ❌ Confusing | ✅ Clear |
| **Logging** | ❌ False positives | ✅ Accurate |
| **Debugging** | ❌ Difficult | ✅ Easy |
| **Thread Safety** | ❌ Unsafe | ✅ Safe |

---

## Testing

### Test the Fix

Run the automated test:
```bash
python tests/test_error_page_and_widget_fixes.py
```

Expected output:
```
TEST 2: Safe Widget Update Helper Function
  ✓ safe_widget_update function exists
  ✓ Function checks widget existence with winfo_exists()
  ✓ Function catches TclError specifically
  ✓ TclError logged as debug (not error)

TEST 5: TclError Separate Exception Handling
  ✓ TclError caught before general Exception (correct order)
  ✓ TclError logged as info/debug (not error)
  ✓ Comment explains TclError is expected behavior
```

---

## Code Locations

**Helper Function:** `src/nextcloud_restore_and_backup-v9.py` lines 96-128

**Usage Examples:**
- `set_restore_progress()` - line 6527
- `auto_extract_backup()` - lines 6586-6743
- `_restore_auto_thread()` - lines 7747-7831

**Exception Handler:** `src/nextcloud_restore_and_backup-v9.py` line 8101

---

**Status:** ✅ Implemented, Tested, and Verified
**Impact:** Critical stability improvement
**Breaking Changes:** None
